Workbook

Sheet Claude Log

Sheet איכות סביבה אי התאמות
B1: מס טופס: - טופס מעקב אי התאמות ופעולות מתקנות
B2: עדכון 10/5//2022
B3: עורך:
B4: איכות סביבה
B5: פירוט אי התאמה או ממצאים | C5: תאריך | D5: סיבת שורש | E5: פעולת תיקון( עצירת האי התאמה) | F5: פעולה מתקנת נדרשת | G5: אחראי | H5: מועד לביצוע | I5: סטטוס | J5: הערות
B6: זליגת שמן בחוות מיכלים למעצרה | C6: 44934 | D6: תקינות הצנרת | E6: ספיחה של השמן הנוזל | F6: תיקון הצנרת וניקוי מהיר של האזור | G6: אחזקה | H6: 44934 | I6: בוצע
B7: אי סדר באזור האחסון של פסולת קרטון | C7: 44941 | D7: חוסר ארגון באזור האחסון | E7: סידור אזור האחסון | F7: פינוי קרטונים בתדירות גבוהה יותר | G7: חצר | H7: 44942 | I7: בוצע
B8: זליגת שמן באזור טיגון | C8: 44969 | D8: תיקון זמני בוצע במקרה 1 | E8: ביצוע אחזקה מונעת | G8: אחזקה | H8: 44969 | I8: בוצע | J8: תוקן מידית שמן לא זלג לניקוזים
B9: פיזור פסולת עץ באזור המפעל | C9: 44976 | D9: חוסר טיפול תקין בפסולת | E9: ניקיון האזור פסולת העץ | F9: ארגון וניקוי שטח ופינוי פסולת עץ בתדירות גובהה יותר | G9: עובדי חצר | H9: 44976 | I9: בוצע
B10: אי סדר באזור המלגזות | C10: 44983 | D10: חוסר ארגון באזור המלגזות | E10: סידור אזור המלגזות וניקון האזור | F10: פיקוח של מנהל המחלקה לסדר באזור | G10: עובדי חצר | H10: 45012 | I10: בוצע
B11: שפכים עובד ביעילות נמוכה בוצה לא יצאת מהמתקן | C11: 44997 | D11: עומס על מתקן השפכים | E11: הורדת ספיקות ותיקון הצנטרפוגה | F11: החלפת הצנטרפוגה ומתקן השפכים | G11: מיכאל | H11: 45004 | I11: בוצע
B12: עומס על מערכת השטיפות | C12: 45004 | D12: תהליך הייצור הנוכחי גרם לבריחה וסתימה של הבור חול | E12: הזמנה ביובית לפתיחת הסתימה | F12: שיפור תהליך הקילוף והרחבת המערכת הבור | G12: מיכאל | H12: 45188 | I12: בוצע | J12: כחלק מתוכנית שדרוג המערך השפכים ישודרג גם בור החול
B13: אי ניקוי רצפים באזור התפעול | C13: 45004 | D13: איכויות מתקן השפכים | E13: אין | F13: נרכש סוחט חדש לטיפול יעיל יותר השפכים | G13: מיכאל | H13: 45188 | I13: בוצע
B14: ברז מים בייצור שנשר פתוח | C14: 45025 | D14: חוסר תכנון ניקיון תקין | E14: ניקיון מידי של האזור | F14: חידוד על ידי המפעיל על סנדר וניקיון | G14: מנהל תפעול+ מיכאל | H14: 45032 | I14: בוצע | J14: העובדים הודרכו על ביצוע ניקיון בשוטף
B15: זליגת שפכים לשטח השפכים | C15: 45032 | D15: עבודה לא לפי הנהלים | E15: סגירת הברז | F15: חידוד הנהלים ושילוט נכון של הברז | G15: טכנולוג+ מפעילים | H15: 45032 | I15: בוצע | J15: נמצא ברז פתוח
B16: נזילות מים באזור השטיפה של תפוחי האדמה | C16: 45039 | D16: תקלה במתקן השפכים | E16: תיקון מיידי של תקלה במתקן השפכים ובדיקת שאר המתקנים | F16: תחזוקה נכונה של המתקן. | G16: מפעיל שפכים+ אחזקה | H16: 45040 | I16: בוצע | J16: הנזילה נעצרה במידי ותוקנה
B17: חומרי גלם לא מאוחסנים על מדפים מתאימים | C17: 45047 | D17: תקלה במערכת השטיפה | E17: תיקון מיידי של תקלה במערכת השטיפה | G17: אחזקה | H17: 45050 | I17: בוצע
B18: אזור רוטוסטרנר מלוכלל בשמן ברצפה | C18: 45047 | D18: מחסור במיקום | E18: סידור המחסן והקפדה על אחסון על מעצרות | F18: הוספו מספר מאצרות | G18: מחסני | H18: 45048 | I18: בוצע
B19: פיצוץ מים וצריכה מופרז בצריכת המים | C19: 45060 | D19: אי המידה בנהלים | E19: ניקיון מידי וספיגה של השמן | F19: חידוד נהלים ואיחסון אריזות | G19: חצר | H19: 45060 | I19: בוצע
B20: נזילה מבור ביוב המוביל שפכים | C20: 45060 | D20: כשל מערכתי של ציוד | E20: תיקון הפיצוץ | G20: טכנולוג | H20: 45060 | I20: בוצע
B21: אחסון קוביות בסיס במיתקן השפכים לא בצורה תקינה בתוך המאצרה | C21: 45070 | D21: נזק מכני על ידי מלגזה לבור ניקוז שפכים | E21: תיקון בור במידי | F21: גידור של הבור | G21: מנהל איכות הסביבה | H21: 45070 | I21: בוצע
B22: אריזות ריקות מפוזרות ליד מחלקת מעוצבים | C22: 45070 | D22: אחסון לקווי | E22: הכנסת קוביה בצורה תקינה למאצרה | F22: חידוד של נהלים | G22: מנהל איכות הסביבה | H22: 45070 | I22: בוצע
B23: נזילת שמן ליד המטגנת | C23: 45078 | D23: אחסון לקווי וטיפול לא נכון באריזות | E23: העברה של האריזות הריקות למקום יעודי לאיחסון | F23: חידוד הנהלים | G23: מנהל איכות הסביבה | H23: 45078 | I23: בוצע
B24: נזילת שפכים מבור הרוטו סטרנר | C24: 45096 | D24: חוסר בתחזוקה שותפת | E24: תיקון מקור הנזילה | F24: יותר דגש על תחזוקת מונעת | G24: מנהל טכני | H24: 45168 | I24: בוצע
B25: נזילת שמן מקוביה | C25: 45109 | D25: תקלה במערעת המשאבות | E25: תיקון התקלה | F25: בדיקות בתדירות יותר גבוהה | G25: מפעיל שפכים+ אחזקה | H25: 45109 | I25: בוצע
B26: נשפף בוצה שפכים ממכולה | C26: 45116 | D26: חוסר הקפדה על הנהלים איחסון נכון | E26: החסנה על מעצרה | F26: חידוד הנהלים איחסון חומרים | G26: מנהל איכות הסביבה | H26: 45116 | I26: בוצע
B27: איזור מלגזות נזילת שמן | C27: 45146 | D27: תקלה מכנית במכולה | E27: תיקון המכולה | G27: מנהל איכות הסביבה | H27: 45146 | I27: בוצע
B28: איזור קרון קילוף בזל נזילה מהקרון | C28: 45166 | D28: חוסר ארגון באזור המלגזות | E28: ספיגה וניקיון של השפך | F28: פיקוח אחרי המחלקת ח"וג | G28: מנהל מפעל | H28: 45166 | I28: בוצע
B29: קוביה לא מסומנת | C29: 45172 | D29: תחזוקה מונעת לקויה | E29: תיקון אזור הנזילה | F29: יש לבדצע תחזוקה מונעת בתדירות גבוהה יותר | G29: מנהל טכני | H29: 45172 | I29: בוצע
B30: גריקנים לא מאוחסנים לפי הנוהל בתוך מעצרה | C30: 45185 | D30: עבודה לא לפי הנהלים | E30: שילוט החומר | F30: הדרכה על בסימון קוביות היוצאות לאזור הפינוי פסולות | G30: מנהלי מחלקות | H30: 45185 | I30: בוצע
B31: נזילות באזור השפכים | C31: 45192 | D31: עבודה לא לפי הנהלים | E31: איחסון לפי הדרישה במעצרה 110% | F31: ריענון למחסנאי | G31: איכות הסביבה | H31: 45192 | I31: בוצע
B32: אזור הקרטונים מלאה בקרטונים לפינוי | C32: 45245 | D32: בעיה בתקינות מכונת הסחיטה | E32: טיפול במערך הסחיטה | F32: יש לבצע אחזקה מונעת בתדירות גובה יותר | G32: איכות הסביבה | H32: 45246 | I32: בוצע
B33: קבלת כימיקלים בצורה לא תקינה איחסון לא תקין | C33: 45259 | D33: עומס פינוי קרטונים | E33: תזמון בתדירות גבוהה יותר פינוים | F33: פינוי בתדירות גבוהה | G33: איכות הסביבה | H33: 45259 | I33: בוצע
B34: אזור מעוצבים איחסון לקוי של חומרים | C34: 45264 | D34: עבודה לא לפי הנהלים | E34: יש לאחסן את הכימיקלים על גבי מעצרות 110% | F34: ריענון למחסנאי | G34: איכות הסביבה | H34: 45264 | I34: בוצע
B35: אזור אריזות ריקות(קרטון,ניילון , עץ) מבולגן | C35: 45280 | D35: חוסר טיפול תקין בפסולת | E35: לאחר שימוש יש לפנות מיד את החומר למקום יעודי | F35: עבודה לא לפי הנוהל | G35: מנהל מחלקת מעוצבים | H35: 45280 | I35: בוצע
B36: שפך ממיכל לבן בשפכים | C36: 45280 | D36: עומס פינוי אריזות ריקות | E36: תזמון בתדירות גבוהה יותר פינוים | F36: פינוי בתדירות גבוהה | G36: איכות הסביבה | H36: 45280 | I36: בוצע
B37: תעלות ניקוז מלאות באיזור המט"ש | C37: 45298 | D37: תקלה במשאבה | E37: תיקון משאבה מיכל לבן בשפכים | F37: תחזוקה נכונה של המתקן. | G37: איכות הסביבה | H37: 45298 | I37: בוצע
B38: פסולת במאצרה באזור הדוודים | C38: 45342 | D38: אי הקפדה על נהלים | E38: שאיבת התעלות | F38: יש לכתוב נוהל מסודר לריקון מאצרות ותעלות ניקוז | G38: איכות הסביבה | H38: 45402 | I38: בוצע
B39: פסולת במאצרה באזור הדוודים | C39: 45342 | D39: אי הקפדה על נהלים | E39: ניקוי ופינוי הפסולת מהמאצרה | F39: בדיקות בתדירות יותר גבוהה | G39: איכות הסביבה | H39: 45342 | I39: בוצע
... B45: נזילה מקו המים החמים באזור הדוודים | C45: 45387 | D45: פגם בקו המים החמים | E45: חיפוי ותיקון הקו הפגום למניעת נזילות נוספות. | F45: תכנון לוח זמנים לבדיקות שלמות הקווים | G45: מנהל טכני | H45: 45387 | I45: בוצע
...

Sheet בטיחות אי התאמות
A1: מחלקה | B1: מפגע | C1: פעולה מתקנת שיש לבצע | D1: תאריך פתיחה | E1: תאריך לביצוע | F1: אחריות | G1: בוצע
A2: מפעל | B2: מקלחת חרום ללא מים ועקומה ליד האמוניה | C2: לבדוק את זרימת המים ולישר את המחלקת | D2: 44935 | F2: מנהל אחזקה | G2: בוצע
A3: אחזקה | B3: מלחצים לא מחוזקים לשולחן עבודה | C3: לחזק | D3: 44999 | F3: מנהל אחזקה | G3: בוצע
A4: אחזקה | B4: ארקה לשולחן ריתוך מחוץ למחלקה | C4: חובה | D4: 44999 | F4: מנהל אחזקה | G4: בוצע
A5: אחזקה | B5: באזור הריתוך בחוץ חובה קיר הגנה על העיניים לעוברים והעובדים בסביבה | C5: להשלים קיר הגנה | D5: 44999 | F5: מנהל אחזקה | G5: בוצע
A6: שפכים | B6: מתקן שטיפת עיניים במט"ש שבורה | C6: להחליף, יש חדש | D6: 45006 | F6: אחזקה | G6: בוצע
A7: חומר גלם | B7: ארון חשמל בחומר גלם פתוח | C7: אבקש לסגור ארונות חשמל | D7: 45006 | F7: מנהל חומר גלם | G7: בוצע
A8: מעוצבים | B8: פודס במוצבים חלקה סכנת נפילה | C8: להחליף | D8: 45018 | F8: מנהל ייצור +מנהל אחזקה | G8: בוצע
A9: מפעל | B9: חסר שרשרת בגנה למהפך תפ"א במוצבים | C9: להשלים | D9: 45018 | F9: מנהל אחזקה | G9: בוצע
A10: ייצור | B10: ריצפת אפוקסי שבורה במעוצבים | C10: תיקון | D10: 45018 | F10: מנהל ייצור | G10: בוצע
A11: מעצבים | B11: לוח הפעלה של המרים במעוצבים לא תקינה | C11: חשמל | D11: 45018 | F11: חשמלאי | G11: בוצע
A12: כלל מפעל | B12: שער ירוק נפגע מכלי רכב | C12: טיפול מידי | D12: 45048 | F12: אחזקה | G12: בוצע
A13: כלל מפעל | B13: שער אדום לשנות עין אלקטורני | C13: להגביה את עין עצירה | D13: 45048 | F13: אחזקה | G13: בוצע
... A21: שער | B21: נקודות חשמל חדשות בחדר שומר | C21: להתקין | D21: 45140 | F21: אחזקה | G21: בוצע
A22: ייצור טוגנים | B22: חובה לעבוד עם קסדה ליד העגורן | D22: 45274 | F22: מנהל ייצור טוגנים | G22: בוצע
A23: כלל מפעל | B23: אין לחסום נקודות מי כיבוי | D23: 45274 | F23: כולם | G23: בוצע
A24: מעוצבים | B24: מכסים לתעלות שבורות | D24: 45274 | F24: אחזקה | G24: בוצע
A25: ייצור טוגנים | B25: מכסים לתעלות בבור חול חסר | C25: יבוצע ביום שישי התעלה בתוך הבור בזמן הניקיון | D25: 45274 | E25: 45303 | F25: ממונה בטיחות | G25: בוצע
A26: מחסן אריזות | B26: מיגון למדפים במחסן קרטונים | D26: 45280 | F26: אחזקה | G26: בוצע
A27: ייצור טוגנים | B27: כובעי חבטה לעובדי אחזקה | D27: 45280 | F27: אחזקה | G27: בוצע
A28: כלל מחלקות הייצור | B28: כובעי חבטה לעובדי אחזקה/חשמלאים בזמן העבודה בייצור | C28: יש לדאוג כי עובדי האחזקה והחשמלאים משתמשים כובעי חבטה | D28: 45280 | F28: מנהל אחזקה/ מנהל טכני | G28: בוצע
A29: אחזקה | B29: עמוד עקום במדרגות עלייה לחדר מכונות אמוניה | C29: יש לטפל בעמוד העקום | D29: 45300 | F29: אחזקה | G29: בוצע
A30: אחזקה | B30: ארון כיבוי אש חסום | C30: יש לפנות גישה לארון | D30: 45300 | F30: מנהל אחזקה/ מנהל טכני | G30: בוצע
A31: אחזקה | B31: אבן משחזת במרחק לא תקין | C31: להרחיק בהתאם לדרישות החוק 1.5 CM | D31: 45300 | F31: מנהל אחזקה/ מנהל טכני | G31: בוצע
A32: אחזקה | B32: אבן משחזת לחשמל לא מזמן עבודה | C32: יש לכבות מהחשמל בזמן שלא מבוצעת עבודה עם המשחזת | D32: 45300 | F32: מנהל אחזקה/ מנהל טכני | G32: בוצע
A33: אחזקה | B33: בלגן במחלקה | C33: יש לסדר את המחלקה | D33: 45300 | F33: מנהל אחזקה/ מנהל טכני | G33: בוצע
A34: אחזקה | B34: בלוני חמצן לא קשורים | C34: יש לקשור בלונים לקיר עם שרשרת | D34: 45300 | F34: מנהל אחזקה/ מנהל טכני | G34: בוצע
A35: אחזקה | B35: בלוני חמצן ללא מכסה מגן | C35: יש לסגור בלונים עם מכסה מגן | D35: 45300 | F35: מנהל אחזקה/ מנהל טכני | G35: בוצע
A36: אריזה | B36: חדר חשמל ליד האריזה פתוח+ ארון חשמל פתוח | C36: יש לדאוג שחדר חשמל נעול וארונות סגורים | D36: 45300 | F36: חשמלאים | G36: בוצע
A37: חצר | B37: משטחים צמודים לחדר שנאים הראשי | C37: יש להזיז משטחים לפחות מטר מחדר שנאים( על פי תקן כבאות) | D37: 45300 | F37: מנהל חצר ותוצ"ג | G37: בוצע
A38: חצר | B38: ארון כיבוי אש + מקלחון חירום חסומים ליד אזור מילוי אמוניה | C38: יש להזיז ולא לחסום אזור ארונות כיבוי/משטפות/אזור מילוי וריקון אמוניה | D38: 45300 | F38: מנהל חצר ותוצ"ג | G38: בוצע
A39: חצר | B39: תעלה ליד נבובה הבטון שבור | C39: יש לתקן בטון | D39: 45300 | F39: אחזקה/מנהל חצר ותוצ"ג | G39: בוצע
... A43: ייצור טוגנים(קלופים) | B43: יש להוסיף שלט חובה קסדות באזור הקלופים | C43: יש להזמין שלט | D43: 45300 | F43: מנהל קילופים | G43: בוצע
A44: מעוצבים | B44: קושי בהרמת גלילים במחלקת אריזה במעוצבים | C44: יש לחפש עגלה תפעולית להרמת גלילים | D44: 45300 | F44: מנהל מעוצבים | G44: בוצע | H44: לא אושר יש להרים גליל 2 אנשים
A45: מעוצבים | B45: כימיקלים לא על מעצרות במחלקת אריזה וחדר כימיקלים במעוצבים | C45: יש לרכוש 2 מאצרות קטנות לאחסון כימיקלים | D45: 45300 | F45: מנהל מעוצבים | G45: בוצע
A46: מעוצבים | B46: תעלה עקומה ליד הקוטר | C46: יש לתקן תעלה ליד הקוטר חשש לנפילה | D46: 45300 | F46: מנהל מעוצבים | G46: בוצע
A47: מעוצבים | B47: מיקרו סוויץ הגנה לא תקין במקסר | C47: יש לבדוק מיקרו סוויץ במקסר ולהחליפו | D47: 45300 | F47: חשמלאים/מנהל מעוצבים | G47: בוצע
A48: מעוצבים | B48: ונטה לא עובדת בחדר שקילות (סכנת שאיפת של אבקות) | C48: יש לטפל בווטה עד אז חובה שימוש במסכות אבק | D48: 45300 | F48: מנהל מעוצבים/ אחזקה | G48: בוצע | H48: יש לעבוד עם מסכת אבק
A49: מעוצבים | B49: עמוד שרשרות שבור | C49: יש לתקן את העמוד | D49: 45300 | F49: מנהל מעוצבים/ אחזקה | G49: בוצע
A50: מעצבים | B50: תאורת יציאת חירום במשרד של רומן+ מעבדה לא עובדות | C50: יש לבדוק שלט תאורות חירום (לא עובד בדיקה) | D50: 45300 | F50: חשמלאים | G50: בוצע
...

Sheet סיכום בטיחות - שקופית
B2: סיכום אי התאמות בטיחות - דוח שנתי 2025
B3: תאריך הפקה: 06/04/2026
B5: 📊 סיכום כללי | F5: 📈 מדדים עיקריים
B7: סטטוס | C7: כמות | D7: אחוז | F7: =C12 -> 126 | G7: =C9+C10+C11 -> 2 | H7: =C8 -> 124
B8: ✅ בוצע | C8: =COUNTIFS('בטיחות אי התאמות'!D:D,">="&DATE(2025,1,1),'בטיחות אי התאמות'!D:D,"<"&DATE(2027,1,1),'בטיחות אי התאמות'!G:G,"בוצע") -> 124 | D8: =IF(C12>0,C8/C12,0) -> 0.98412698 | F8: סה"כ ליקויים | G8: פתוחים / לא בוצע | H8: בוצעו ונסגרו
B9: 🔄 בתהליך | C9: =COUNTIFS('בטיחות אי התאמות'!D:D,">="&DATE(2025,1,1),'בטיחות אי התאמות'!D:D,"<"&DATE(2027,1,1),'בטיחות אי התאמות'!G:G,"בתהליך") -> 0 | D9: =IF(C12>0,C9/C12,0) -> 0
B10: ❌ לא בוצע | C10: =COUNTIFS('בטיחות אי התאמות'!D:D,">="&DATE(2025,1,1),'בטיחות אי התאמות'!D:D,"<"&DATE(2027,1,1),'בטיחות אי התאמות'!G:G,"לא בוצע") -> 2 | D10: =IF(C12>0,C10/C12,0) -> 0.015873016
B11: 👁 במעקב | C11: =COUNTIFS('בטיחות אי התאמות'!D:D,">="&DATE(2025,1,1),'בטיחות אי התאמות'!D:D,"<"&DATE(2027,1,1),'בטיחות אי התאמות'!G:G,"במעקב") -> 0 | D11: =IF(C12>0,C11/C12,0) -> 0
B12: סה"כ | C12: =SUM(C8:C11) -> 126 | D12: =IF(C12>0,1,0) -> 1
B16: 📝 הערות לליקויים הפתוחים
B17: 🔴 מחסני יבולים – זוהו 12 ליקויים מהותיים בסיור בטיחות. דורש תכנית עבודה מקיפה וטיפול דחוף.
B18: 🔴 כלל מפעל – תוכנית סימון כבישים ותמרורים התקבלה, טרם יצאה לביצוע.
B24: 📋 פילוח לפי מחלקה - מספר אי התאמות (2025)
B26: מחלקה | C26: סה"כ | D26: בוצע | E26: פתוח/לא בוצע
B27: ייצור טוגנים | C27: =COUNTIFS('בטיחות אי התאמות'!A:A,"ייצור טוגנים",'בטיחות אי התאמות'!D:D,">="&DATE(2025,1,1),'בטיחות אי התאמות'!D:D,"<"&DATE(2027,1,1)) -> 30 | D27: =COUNTIFS('בטיחות אי התאמות'!A:A,"ייצור טוגנים",'בטיחות אי התאמות'!D:D,">="&DATE(2025,1,1),'בטיחות אי התאמות'!D:D,"<"&DATE(2027,1,1),'בטיחות אי התאמות'!G:G,"בוצע") -> 30 | E27: =C27-D27 -> 0
B28: חצר | C28: =COUNTIFS('בטיחות אי התאמות'!A:A,"חצר",'בטיחות אי התאמות'!D:D,">="&DATE(2025,1,1),'בטיחות אי התאמות'!D:D,"<"&DATE(2027,1,1)) -> 18 | D28: =COUNTIFS('בטיחות אי התאמות'!A:A,"חצר",'בטיחות אי התאמות'!D:D,">="&DATE(2025,1,1),'בטיחות אי התאמות'!D:D,"<"&DATE(2027,1,1),'בטיחות אי התאמות'!G:G,"בוצע") -> 18 | E28: =C28-D28 -> 0
B29: מעוצבים | C29: =COUNTIFS('בטיחות אי התאמות'!A:A,"מעוצבים",'בטיחות אי התאמות'!D:D,">="&DATE(2025,1,1),'בטיחות אי התאמות'!D:D,"<"&DATE(2027,1,1)) -> 17 | D29: =COUNTIFS('בטיחות אי התאמות'!A:A,"מעוצבים",'בטיחות אי התאמות'!D:D,">="&DATE(2025,1,1),'בטיחות אי התאמות'!D:D,"<"&DATE(2027,1,1),'בטיחות אי התאמות'!G:G,"בוצע") -> 17 | E29: =C29-D29 -> 0
B30: אריזה | C30: =COUNTIFS('בטיחות אי התאמות'!A:A,"אריזה",'בטיחות אי התאמות'!D:D,">="&DATE(2025,1,1),'בטיחות אי התאמות'!D:D,"<"&DATE(2027,1,1)) -> 16 | D30: =COUNTIFS('בטיחות אי התאמות'!A:A,"אריזה",'בטיחות אי התאמות'!D:D,">="&DATE(2025,1,1),'בטיחות אי התאמות'!D:D,"<"&DATE(2027,1,1),'בטיחות אי התאמות'!G:G,"בוצע") -> 16 | E30: =C30-D30 -> 0
B31: שפכים | C31: =COUNTIFS('בטיחות אי התאמות'!A:A,"שפכים",'בטיחות אי התאמות'!D:D,">="&DATE(2025,1,1),'בטיחות אי התאמות'!D:D,"<"&DATE(2027,1,1)) -> 17 | D31: =COUNTIFS('בטיחות אי התאמות'!A:A,"שפכים",'בטיחות אי התאמות'!D:D,">="&DATE(2025,1,1),'בטיחות אי התאמות'!D:D,"<"&DATE(2027,1,1),'בטיחות אי התאמות'!G:G,"בוצע") -> 17 | E31: =C31-D31 -> 0
B32: חומר גלם | C32: =COUNTIFS('בטיחות אי התאמות'!A:A,"חומר גלם",'בטיחות אי התאמות'!D:D,">="&DATE(2025,1,1),'בטיחות אי התאמות'!D:D,"<"&DATE(2027,1,1)) -> 18 | D32: =COUNTIFS('בטיחות אי התאמות'!A:A,"חומר גלם",'בטיחות אי התאמות'!D:D,">="&DATE(2025,1,1),'בטיחות אי התאמות'!D:D,"<"&DATE(2027,1,1),'בטיחות אי התאמות'!G:G,"בוצע") -> 18 | E32: =C32-D32 -> 0
B33: אחזקה | C33: =COUNTIFS('בטיחות אי התאמות'!A:A,"אחזקה",'בטיחות אי התאמות'!D:D,">="&DATE(2025,1,1),'בטיחות אי התאמות'!D:D,"<"&DATE(2027,1,1)) -> 8 | D33: =COUNTIFS('בטיחות אי התאמות'!A:A,"אחזקה",'בטיחות אי התאמות'!D:D,">="&DATE(2025,1,1),'בטיחות אי התאמות'!D:D,"<"&DATE(2027,1,1),'בטיחות אי התאמות'!G:G,"בוצע") -> 8 | E33: =C33-D33 -> 0
B34: כלל מפעל | C34: =COUNTIFS('בטיחות אי התאמות'!A:A,"כלל מפעל",'בטיחות אי התאמות'!D:D,">="&DATE(2025,1,1),'בטיחות אי התאמות'!D:D,"<"&DATE(2027,1,1)) -> 1 | D34: =COUNTIFS('בטיחות אי התאמות'!A:A,"כלל מפעל",'בטיחות אי התאמות'!D:D,">="&DATE(2025,1,1),'בטיחות אי התאמות'!D:D,"<"&DATE(2027,1,1),'בטיחות אי התאמות'!G:G,"בוצע") -> 0 | E34: =C34-D34 -> 1
B35: מחסני יבולים | C35: =COUNTIFS('בטיחות אי התאמות'!A:A,"מחסני יבולים",'בטיחות אי התאמות'!D:D,">="&DATE(2025,1,1),'בטיחות אי התאמות'!D:D,"<"&DATE(2027,1,1)) -> 1 | D35: =COUNTIFS('בטיחות אי התאמות'!A:A,"מחסני יבולים",'בטיחות אי התאמות'!D:D,">="&DATE(2025,1,1),'בטיחות אי התאמות'!D:D,"<"&DATE(2027,1,1),'בטיחות אי התאמות'!G:G,"בוצע") -> 0 | E35: =C35-D35 -> 1
B36: סה"כ (כל המחלקות) | C36: =SUM(C27:C35) -> 126 | D36: =SUM(D27:D35) -> 124 | E36: =SUM(E27:E35) -> 2

Sheet סיכום סביבה - שקופית
B2: סיכום אי התאמות איכות סביבה - דוח שנתי 2025
B5: 📊 סיכום כללי | F5: 📈 מדדים עיקריים
B7: סטטוס | C7: כמות | D7: אחוז | F7: =C12 -> 56 | G7: =C10+C11 -> 2 | H7: =C8 -> 54
B8: ✅ בוצע | C8: =COUNTIFS('איכות סביבה אי התאמות'!$C$6:$C$126,">="&DATE(2025,1,1),'איכות סביבה אי התאמות'!$C$6:$C$126,"<"&DATE(2027,1,1),'איכות סביבה אי התאמות'!$I$6:$I$126,"בוצע")+COUNTIFS('איכות סביבה אי התאמות'!$C$6:$C$126,">="&DATE(2025,1,1),'איכות סביבה אי התאמות'!$C$6:$C$126,"<"&DATE(2027,1,1),'איכות סביבה אי התאמות'!$I$6:$I$126,"בוצע ") -> 54 | D8: =IF(C12>0,C8/C12,"") -> 0.96428571 | F8: סה"כ ליקויים | G8: פתוחים / במעקב | H8: בוצעו ונסגרו
B9: 🔄 בתהליך | C9: =COUNTIFS('איכות סביבה אי התאמות'!$C$6:$C$126,">="&DATE(2025,1,1),'איכות סביבה אי התאמות'!$C$6:$C$126,"<"&DATE(2027,1,1),'איכות סביבה אי התאמות'!$I$6:$I$126,"בתהליך") -> 0 | D9: =IF(C12>0,C9/C12,"") -> 0
B10: ❌ לא בוצע | C10: =COUNTIFS('איכות סביבה אי התאמות'!$C$6:$C$126,">="&DATE(2025,1,1),'איכות סביבה אי התאמות'!$C$6:$C$126,"<"&DATE(2027,1,1),'איכות סביבה אי התאמות'!$I$6:$I$126,"לא בוצע") -> 0 | D10: =IF(C12>0,C10/C12,"") -> 0
B11: 👁 במעקב | C11: =COUNTIFS('איכות סביבה אי התאמות'!$C$6:$C$126,">="&DATE(2025,1,1),'איכות סביבה אי התאמות'!$C$6:$C$126,"<"&DATE(2027,1,1),'איכות סביבה אי התאמות'!$I$6:$I$126,"במעקב") -> 2 | D11: =IF(C12>0,C11/C12,"") -> 0.035714286
B12: סה"כ | C12: =SUM(C8:C11) -> 56 | D12: =IF(C12>0,1,"") -> 1
B16: 📝 הערות לליקויים הפתוחים / במעקב
B17: 🟠 הורדה של שפכים בצורה לא מדודה גורמת לעומס כימיקלים על המט"ש – נכתב נוהל הורדה של שפכים. סטטוס: במעקב.
B18: 🟠 השלכת פסולת מסוג תפוחי אדמה וציפס לתוך תעלות הביוב – נדרש נוהל הורדה מסודר. סטטוס: במעקב.
B24: 📋 פילוח לפי מיקום/אזור - מספר אי התאמות (2025)
B26: מיקום / אזור | C26: סה"כ | D26: בוצע | E26: פתוח/במעקב
B27: אזור ייצור / טיגון | C27: 17 | D27: 17 | E27: 0
B28: מט"ש / שפכים | C28: 14 | D28: 12 | E28: 2
B29: מחסן כימיקלים | C29: 7 | D29: 7 | E29: 0
B30: חצר | C30: 5 | D30: 5 | E30: 0
B31: חוות מיכלים / אחסון | C31: 4 | D31: 4 | E31: 0
B32: מערכות אוויר / פליטות | C32: 4 | D32: 4 | E32: 0
B33: אזור אריזה / פסולת | C33: 4 | D33: 4 | E33: 0
B34: כללי | C34: 1 | D34: 1 | E34: 0
B35: סה"כ (כל האזורים) | C35: 56 | D35: 54 | E35: 2
